Workbook

Sheet I. Summary
C1: CrossCover Insurance Services, LLC. | H1: Version: 3/28/2025
C2: Submission/Renewal/Endorsement Request Template
C3: New or changes to Coverage/Limits must be confirmed by a CrossCover Underwriter
A5: Producer Company | C5: =IF(SummaryImport!B2 = "", "", SummaryImport!B2)
A6: Producer Name | C6: =IF(SummaryImport!C2 = "", "", SummaryImport!C2)
A7: Producer Email | C7: =IF(SummaryImport!D2 = "", "", SummaryImport!D2)
A8: Producer Assistant Name | C8: =IF(SummaryImport!E2 = "", "", SummaryImport!E2)
A9: Producer Assistant Email | C9: =IF(SummaryImport!F2 = "", "", SummaryImport!F2)
A10: Named Insured | C10: =IF(SummaryImport!G2 = "", "", SummaryImport!G2)
A11: DBA | C11: =IF(SummaryImport!H2 = "", "", SummaryImport!H2)
A12: Care Of | C12: =IF(SummaryImport!I2 = "", "", SummaryImport!I2)
A13: Mailing Address Street | C13: =IF(SummaryImport!J2 = "", "", SummaryImport!J2)
A14: Mailing Address City | C14: =IF(SummaryImport!K2 = "", "", SummaryImport!K2)
A15: Mailing Address State | C15: =IF(SummaryImport!L2 = "", "--", SummaryImport!L2) -> --
A16: Mailing Address Zip | C16: =IF(SummaryImport!M2 = "", "", SummaryImport!M2)
A17: Insured Contact Name | C17: =IF(SummaryImport!N2 = "", "", SummaryImport!N2)
A18: Insured Contact Email | C18: =IF(SummaryImport!O2 = "", "", SummaryImport!O2)
A19: Insured Contact Phone | C19: =IF(SummaryImport!P2 = "", "", SummaryImport!P2)
A21: Request Type | C21: New Submission | E21: *Please select request type
A22: =IF(C21 = "New Submission", 1, IF(C21 = "Renewal Submission", 2, 3)) -> 1
A23: Submission/Renewal Request: | D23: Please complete sheets I, II, III, IV of this spreadsheet.
A24: Effective Date | C24: =NOW() -> 45994.543 | D24: If existing locations are included on sheet 'V. Existing Locations', please revise values on this sheet.
A25: Expiration Date | C25: =DATE(YEAR(C24) + 1, MONTH(C24), DAY(C24)) -> 46359 | D25: Only new locations need to be added to Sheet 'III. New Locations'.
A26: Expiring Submission ID (If renewal) | C26: =IF(SummaryImport!A2 = "", "0", SummaryImport!A2) -> 0 | D26: To be remove from the renewal change status to 'Removal Requested' in sheet 'V. Existing Locations'
A28: Endorsement Request:
A29: SubmissionID | C29: =IF(SummaryImport!A2 = "", "", SummaryImport!A2)
A30: Effective Date of Change
A32: =IF(C21 = "New Submission", 1, IF(C21 = "Renewal Submission", 1, 0)) -> 1 | B32: *Please select 'Yes' to any applicable requests below:
B33: No | C33: Change Insured Name | E33: <Enter new Insured Name here>
B34: No | C34: Change DBA Name | E34: <Enter new DBA Name here>
B35: No | C35: Add/Change Additional Named Insureds | E35: <Enter new additional names here>
B36: No | C36: Add/Change Loss Payee or Mortgagee | E36: <Enter new Loss Payee here>
B38: No | C38: Change Insured Mailing Address | E38: <Enter new Mailing Address here>
B40: No | C40: Add Location(s) | E40: *See 'III. New Locations' XLS tab to add new location data
B41: No | C41: Remove Location(s) | E41: *See 'V. Existing Locations' XLS tab to change location STATUS to 'Remove'
B42: No | C42: Revise Location Value(s) | E42: *See 'V. Existing Locations' XLS tab to change location STATUS to 'Revise' values
B44: No | C44: Add Peril(s) | E44: <Describe new peril request here>
B45: No | C45: Remove Peril(s) | E45: <Describe Peril removal request here>
B47: No | C47: Add Form(s) | E47: <Describe new form request here>
B48: No | C48: Remove Forms(s) | E48: <Describe form removal request here>
...

Sheet II. App Questions
A3: General Information
B5: No | C5: 1. Has any property policy or coverage been declined, cancelled, or non-renewed during the prior 3 years (not applicable in MO)?
C6: <Explain Yes>
B8: No | C8: 2. Is the applicant a S-Chapter Corporation, partnership, or any other type of sole proprietor organization?
C9: <Explain Yes>
B11: No | C11: 3. If yes to No. 2 above, has the net income been negative for 2 of the prior 3 years? If yes, attach financials or tax returns for prior 3 years.
B14: No | C14: 4. During the last 5 years (10 years in RI), has any applicant been indicted for or convicted of the crime of fraud, bribery, arson, or any other arson-related crime in connection with this or any other property?
C15: <Explain Yes>
B17: No | C17: 5. Any bankruptcies, tax or credit liens against the applicant in the past 5 years?
C18: <Explain Yes>
B20: No | C20: Removed
B23: No | C23: 7. Apts and Condos: any aluminum distribution wiring within the units?
C24: <Explain Yes>
B26: No | C26: 8. If yes to No. 7, is that aluminum distribution wiring pigtailed or CO/ALR’d at the switches and outlets within the units?
C27: <Explain Yes>

Sheet III. New Locations
C1: Address | G1: =SUM(G3:G2002) -> 0 | H1: =SUM(H3:H2002) -> 0 | I1: =SUM(I3:I2002) -> 0 | J1: =SUM(J3:J2002) -> 0 | K1: =SUM(K3:K2002) -> 0 | L1: =SUM(L3:L2002) -> 0 | M1: Property Details | AD1: Habitational Information | AF1: Earth Movement (Required for CA, OR, WA, HI and AK) | AK1: Wind (Required if within 100 miles of the Atlantic Ocean or Gulf of Mexico)
A2: New Loc # | B2: Location Name | C2: Street Address | D2: City | E2: State | F2: Zip | G2: Building | H2: Contents | I2: Business Interuption | J2: Machinery & Equip. | K2: Other | L2: Location Total | M2: Building SQFT | N2: $/SQFT | O2: Num Buildings | P2: Num Units | Q2: Num Stories | R2: % Sprinklered | S2: % Occupied | T2: Construction | U2: Construction Description | V2: Occupancy | W2: Occupancy Description | X2: ISO ProtClass | Y2: YearBuilt | Z2: Year Upgrade | AA2: Year Roof Replaced | AB2: Describe upgrades and replacement | AC2: removed | AD2: Type of wiring | AE2: Security | AF2: Plan Irregularity | AG2: Soft Story | AH2: Vertical Irregularity | AI2: Tilt-up Anchoring | AJ2: Structural Upgrade | AK2: Roof Geometry | AL2: Roof Covering | AM2: Roof Anchoring | AN2: Roof Sheathing Attach | AO2: Frame Foundation | AP2: Cladding Type | AQ2: Latitude | AR2: Longitude
A3: 1 | L3: =SUM(G3:K3) -> 0 | M3: 1 | N3: =G3/M3 -> 0 | O3: 1 | P3: 1 | Q3: 1 | R3: 0 | S3: 0 | T3: -Unknown- | AC3: 0 | AD3: Unknown | AF3: Unknown | AG3: Unknown | AH3: Unknown | AI3: Unknown | AJ3: Unknown | AK3: Unknown | AL3: Unknown | AM3: Unknown | AN3: Unknown | AO3: Unknown | AP3: Unknown
A4: 2 | L4: =SUM(G4:K4) -> 0 | M4: 1 | N4: =G4/M4 -> 0 | O4: 1 | P4: 1 | Q4: 1 | S4: 0 | T4: -Unknown- | AC4: 0 | AD4: Unknown | AF4: Unknown | AG4: Unknown | AH4: Unknown | AI4: Unknown | AJ4: Unknown | AK4: Unknown | AL4: Unknown | AM4: Unknown | AN4: Unknown | AO4: Unknown | AP4: Unknown
A5: 3 | L5: =SUM(G5:K5) -> 0 | M5: 1 | N5: =G5/M5 -> 0 | O5: 1 | P5: 1 | Q5: 1 | R5: 0 | S5: 0 | T5: -Unknown- | AC5: 0 | AD5: Unknown | AF5: Unknown | AG5: Unknown | AH5: Unknown | AI5: Unknown | AJ5: Unknown | AK5: Unknown | AL5: Unknown | AM5: Unknown | AN5: Unknown | AO5: Unknown | AP5: Unknown
A6: 4 | L6: =SUM(G6:K6) -> 0 | M6: 1 | N6: =G6/M6 -> 0 | O6: 1 | P6: 1 | Q6: 1 | R6: 0 | S6: 0 | T6: -Unknown- | AC6: 0 | AD6: Unknown | AF6: Unknown | AG6: Unknown | AH6: Unknown | AI6: Unknown | AJ6: Unknown | AK6: Unknown | AL6: Unknown | AM6: Unknown | AN6: Unknown | AO6: Unknown | AP6: Unknown
A7: 5 | L7: =SUM(G7:K7) -> 0 | M7: 1 | N7: =G7/M7 -> 0 | O7: 1 | P7: 1 | Q7: 1 | R7: 0 | S7: 0 | T7: -Unknown- | AC7: 0 | AD7: Unknown | AF7: Unknown | AG7: Unknown | AH7: Unknown | AI7: Unknown | AJ7: Unknown | AK7: Unknown | AL7: Unknown | AM7: Unknown | AN7: Unknown | AO7: Unknown | AP7: Unknown
A8: 6 | L8: =SUM(G8:K8) -> 0 | M8: 1 | N8: =G8/M8 -> 0 | O8: 1 | P8: 1 | Q8: 1 | R8: 0 | S8: 0 | T8: -Unknown- | AC8: 0 | AD8: Unknown | AF8: Unknown | AG8: Unknown | AH8: Unknown | AI8: Unknown | AJ8: Unknown | AK8: Unknown | AL8: Unknown | AM8: Unknown | AN8: Unknown | AO8: Unknown | AP8: Unknown
A9: 7 | L9: =SUM(G9:K9) -> 0 | M9: 1 | N9: =G9/M9 -> 0 | O9: 1 | P9: 1 | Q9: 1 | R9: 0 | S9: 0 | T9: -Unknown- | AC9: 0 | AD9: Unknown | AF9: Unknown | AG9: Unknown | AH9: Unknown | AI9: Unknown | AJ9: Unknown | AK9: Unknown | AL9: Unknown | AM9: Unknown | AN9: Unknown | AO9: Unknown | AP9: Unknown
A10: 8 | L10: =SUM(G10:K10) -> 0 | M10: 1 | N10: =G10/M10 -> 0 | O10: 1 | P10: 1 | Q10: 1 | R10: 0 | S10: 0 | T10: -Unknown- | AC10: 0 | AD10: Unknown | AF10: Unknown | AG10: Unknown | AH10: Unknown | AI10: Unknown | AJ10: Unknown | AK10: Unknown | AL10: Unknown | AM10: Unknown | AN10: Unknown | AO10: Unknown | AP10: Unknown
A11: 9 | L11: =SUM(G11:K11) -> 0 | M11: 1 | N11: =G11/M11 -> 0 | O11: 1 | P11: 1 | Q11: 1 | R11: 0 | S11: 0 | T11: -Unknown- | AC11: 0 | AD11: Unknown | AF11: Unknown | AG11: Unknown | AH11: Unknown | AI11: Unknown | AJ11: Unknown | AK11: Unknown | AL11: Unknown | AM11: Unknown | AN11: Unknown | AO11: Unknown | AP11: Unknown
A12: 10 | L12: =SUM(G12:K12) -> 0 | M12: 1 | N12: =G12/M12 -> 0 | O12: 1 | P12: 1 | Q12: 1 | R12: 0 | S12: 0 | T12: -Unknown- | AC12: 0 | AD12: Unknown | AF12: Unknown | AG12: Unknown | AH12: Unknown | AI12: Unknown | AJ12: Unknown | AK12: Unknown | AL12: Unknown | AM12: Unknown | AN12: Unknown | AO12: Unknown | AP12: Unknown
A13: 11 | L13: =SUM(G13:K13) -> 0 | M13: 1 | N13: =G13/M13 -> 0 | O13: 1 | P13: 1 | Q13: 1 | R13: 0 | S13: 0 | T13: -Unknown- | AC13: 0 | AD13: Unknown | AF13: Unknown | AG13: Unknown | AH13: Unknown | AI13: Unknown | AJ13: Unknown | AK13: Unknown | AL13: Unknown | AM13: Unknown | AN13: Unknown | AO13: Unknown | AP13: Unknown
A14: 12 | L14: =SUM(G14:K14) -> 0 | M14: 1 | N14: =G14/M14 -> 0 | O14: 1 | P14: 1 | Q14: 1 | R14: 0 | S14: 0 | T14: -Unknown- | AC14: 0 | AD14: Unknown | AF14: Unknown | AG14: Unknown | AH14: Unknown | AI14: Unknown | AJ14: Unknown | AK14: Unknown | AL14: Unknown | AM14: Unknown | AN14: Unknown | AO14: Unknown | AP14: Unknown
A15: 13 | L15: =SUM(G15:K15) -> 0 | M15: 1 | N15: =G15/M15 -> 0 | O15: 1 | P15: 1 | Q15: 1 | R15: 0 | S15: 0 | T15: -Unknown- | AC15: 0 | AD15: Unknown | AF15: Unknown | AG15: Unknown | AH15: Unknown | AI15: Unknown | AJ15: Unknown | AK15: Unknown | AL15: Unknown | AM15: Unknown | AN15: Unknown | AO15: Unknown | AP15: Unknown
A16: 14 | L16: =SUM(G16:K16) -> 0 | M16: 1 | N16: =G16/M16 -> 0 | O16: 1 | P16: 1 | Q16: 1 | R16: 0 | S16: 0 | T16: -Unknown- | AC16: 0 | AD16: Unknown | AF16: Unknown | AG16: Unknown | AH16: Unknown | AI16: Unknown | AJ16: Unknown | AK16: Unknown | AL16: Unknown | AM16: Unknown | AN16: Unknown | AO16: Unknown | AP16: Unknown
... A89: 87 | L89: =SUM(G89:K89) -> 0 | M89: 1 | N89: =G89/M89 -> 0 | O89: 1 | P89: 1 | Q89: 1 | R89: 0 | S89: 0 | T89: -Unknown- | AC89: 0 | AD89: Unknown | AF89: Unknown | AG89: Unknown | AH89: Unknown | AI89: Unknown | AJ89: Unknown | AK89: Unknown | AL89: Unknown | AM89: Unknown | AN89: Unknown | AO89: Unknown | AP89: Unknown
A90: 88 | L90: =SUM(G90:K90) -> 0 | M90: 1 | N90: =G90/M90 -> 0 | O90: 1 | P90: 1 | Q90: 1 | R90: 0 | S90: 0 | T90: -Unknown- | V90: Unknown | X90: Unknown | Z90: =Y90 -> 0 | AA90: =Y90 -> 0 | AC90: 0 | AD90: Unknown | AF90: Unknown | AG90: Unknown | AH90: Unknown | AI90: Unknown | AJ90: Unknown | AK90: Unknown | AL90: Unknown | AM90: Unknown | AN90: Unknown | AO90: Unknown | AP90: Unknown
A91: 89 | L91: =SUM(G91:K91) -> 0 | M91: 1 | N91: =G91/M91 -> 0 | O91: 1 | P91: 1 | Q91: 1 | R91: 0 | S91: 0 | T91: -Unknown- | V91: Unknown | X91: Unknown | Z91: =Y91 -> 0 | AA91: =Y91 -> 0 | AC91: 0 | AD91: Unknown | AF91: Unknown | AG91: Unknown | AH91: Unknown | AI91: Unknown | AJ91: Unknown | AK91: Unknown | AL91: Unknown | AM91: Unknown | AN91: Unknown | AO91: Unknown | AP91: Unknown
A92: 90 | L92: =SUM(G92:K92) -> 0 | M92: 1 | N92: =G92/M92 -> 0 | O92: 1 | P92: 1 | Q92: 1 | R92: 0 | S92: 0 | T92: -Unknown- | V92: Unknown | X92: Unknown | Z92: =Y92 -> 0 | AA92: =Y92 -> 0 | AC92: 0 | AD92: Unknown | AF92: Unknown | AG92: Unknown | AH92: Unknown | AI92: Unknown | AJ92: Unknown | AK92: Unknown | AL92: Unknown | AM92: Unknown | AN92: Unknown | AO92: Unknown | AP92: Unknown
A93: 91 | L93: =SUM(G93:K93) -> 0 | M93: 1 | N93: =G93/M93 -> 0 | O93: 1 | P93: 1 | Q93: 1 | R93: 0 | S93: 0 | T93: -Unknown- | V93: Unknown | X93: Unknown | Z93: =Y93 -> 0 | AA93: =Y93 -> 0 | AC93: 0 | AD93: Unknown | AF93: Unknown | AG93: Unknown | AH93: Unknown | AI93: Unknown | AJ93: Unknown | AK93: Unknown | AL93: Unknown | AM93: Unknown | AN93: Unknown | AO93: Unknown | AP93: Unknown
A94: 92 | L94: =SUM(G94:K94) -> 0 | M94: 1 | N94: =G94/M94 -> 0 | O94: 1 | P94: 1 | Q94: 1 | R94: 0 | S94: 0 | T94: -Unknown- | V94: Unknown | X94: Unknown | Z94: =Y94 -> 0 | AA94: =Y94 -> 0 | AC94: 0 | AD94: Unknown | AF94: Unknown | AG94: Unknown | AH94: Unknown | AI94: Unknown | AJ94: Unknown | AK94: Unknown | AL94: Unknown | AM94: Unknown | AN94: Unknown | AO94: Unknown | AP94: Unknown
A95: 93 | L95: =SUM(G95:K95) -> 0 | M95: 1 | N95: =G95/M95 -> 0 | O95: 1 | P95: 1 | Q95: 1 | R95: 0 | S95: 0 | T95: -Unknown- | V95: Unknown | X95: Unknown | Z95: =Y95 -> 0 | AA95: =Y95 -> 0 | AC95: 0 | AD95: Unknown | AF95: Unknown | AG95: Unknown | AH95: Unknown | AI95: Unknown | AJ95: Unknown | AK95: Unknown | AL95: Unknown | AM95: Unknown | AN95: Unknown | AO95: Unknown | AP95: Unknown
A96: 94 | L96: =SUM(G96:K96) -> 0 | M96: 1 | N96: =G96/M96 -> 0 | O96: 1 | P96: 1 | Q96: 1 | R96: 0 | S96: 0 | T96: -Unknown- | V96: Unknown | X96: Unknown | Z96: =Y96 -> 0 | AA96: =Y96 -> 0 | AC96: 0 | AD96: Unknown | AF96: Unknown | AG96: Unknown | AH96: Unknown | AI96: Unknown | AJ96: Unknown | AK96: Unknown | AL96: Unknown | AM96: Unknown | AN96: Unknown | AO96: Unknown | AP96: Unknown
A97: 95 | L97: =SUM(G97:K97) -> 0 | M97: 1 | N97: =G97/M97 -> 0 | O97: 1 | P97: 1 | Q97: 1 | R97: 0 | S97: 0 | T97: -Unknown- | V97: Unknown | X97: Unknown | Z97: =Y97 -> 0 | AA97: =Y97 -> 0 | AC97: 0 | AD97: Unknown | AF97: Unknown | AG97: Unknown | AH97: Unknown | AI97: Unknown | AJ97: Unknown | AK97: Unknown | AL97: Unknown | AM97: Unknown | AN97: Unknown | AO97: Unknown | AP97: Unknown
A98: 96 | L98: =SUM(G98:K98) -> 0 | M98: 1 | N98: =G98/M98 -> 0 | O98: 1 | P98: 1 | Q98: 1 | R98: 0 | S98: 0 | T98: -Unknown- | V98: Unknown | X98: Unknown | Z98: =Y98 -> 0 | AA98: =Y98 -> 0 | AC98: 0 | AD98: Unknown | AF98: Unknown | AG98: Unknown | AH98: Unknown | AI98: Unknown | AJ98: Unknown | AK98: Unknown | AL98: Unknown | AM98: Unknown | AN98: Unknown | AO98: Unknown | AP98: Unknown
A99: 97 | L99: =SUM(G99:K99) -> 0 | M99: 1 | N99: =G99/M99 -> 0 | O99: 1 | P99: 1 | Q99: 1 | R99: 0 | S99: 0 | T99: -Unknown- | V99: Unknown | X99: Unknown | Z99: =Y99 -> 0 | AA99: =Y99 -> 0 | AC99: 0 | AD99: Unknown | AF99: Unknown | AG99: Unknown | AH99: Unknown | AI99: Unknown | AJ99: Unknown | AK99: Unknown | AL99: Unknown | AM99: Unknown | AN99: Unknown | AO99: Unknown | AP99: Unknown
A100: 98 | L100: =SUM(G100:K100) -> 0 | M100: 1 | N100: =G100/M100 -> 0 | O100: 1 | P100: 1 | Q100: 1 | R100: 0 | S100: 0 | T100: -Unknown- | V100: Unknown | X100: Unknown | Z100: =Y100 -> 0 | AA100: =Y100 -> 0 | AC100: 0 | AD100: Unknown | AF100: Unknown | AG100: Unknown | AH100: Unknown | AI100: Unknown | AJ100: Unknown | AK100: Unknown | AL100: Unknown | AM100: Unknown | AN100: Unknown | AO100: Unknown | AP100: Unknown
A101: 99 | L101: =SUM(G101:K101) -> 0 | M101: 1 | N101: =G101/M101 -> 0 | O101: 1 | P101: 1 | Q101: 1 | R101: 0 | S101: 0 | T101: -Unknown- | V101: Unknown | X101: Unknown | Z101: =Y101 -> 0 | AA101: =Y101 -> 0 | AC101: 0 | AD101: Unknown | AF101: Unknown | AG101: Unknown | AH101: Unknown | AI101: Unknown | AJ101: Unknown | AK101: Unknown | AL101: Unknown | AM101: Unknown | AN101: Unknown | AO101: Unknown | AP101: Unknown
... A354: 352 | L354: =SUM(G354:K354) -> 0 | M354: 1 | N354: =G354/M354 -> 0 | O354: 1 | P354: 1 | Q354: 1 | R354: 0 | S354: 0 | T354: -Unknown- | V354: Unknown | X354: Unknown | Z354: =Y354 -> 0 | AA354: =Y354 -> 0 | AC354: 0 | AD354: Unknown | AF354: Unknown | AG354: Unknown | AH354: Unknown | AI354: Unknown | AJ354: Unknown | AK354: Unknown | AL354: Unknown | AM354: Unknown | AN354: Unknown | AO354: Unknown | AP354: Unknown
A355: 353 | E355: -- | G355: 0 | H355: 0 | I355: 0 | J355: 0 | K355: 0 | L355: =SUM(G355:K355) -> 0 | M355: 1 | N355: =G355/M355 -> 0 | O355: 1 | P355: 1 | Q355: 1 | R355: 0 | S355: 0 | T355: -Unknown- | V355: Unknown | X355: Unknown | Z355: =Y355 -> 0 | AA355: =Y355 -> 0 | AC355: 0 | AD355: Unknown | AF355: Unknown | AG355: Unknown | AH355: Unknown | AI355: Unknown | AJ355: Unknown | AK355: Unknown | AL355: Unknown | AM355: Unknown | AN355: Unknown | AO355: Unknown | AP355: Unknown
A356: 354 | E356: -- | G356: 0 | H356: 0 | I356: 0 | J356: 0 | K356: 0 | L356: =SUM(G356:K356) -> 0 | M356: 1 | N356: =G356/M356 -> 0 | O356: 1 | P356: 1 | Q356: 1 | R356: 0 | S356: 0 | T356: -Unknown- | V356: Unknown | X356: Unknown | Z356: =Y356 -> 0 | AA356: =Y356 -> 0 | AC356: 0 | AD356: Unknown | AF356: Unknown | AG356: Unknown | AH356: Unknown | AI356: Unknown | AJ356: Unknown | AK356: Unknown | AL356: Unknown | AM356: Unknown | AN356: Unknown | AO356: Unknown | AP356: Unknown
A357: 355 | E357: -- | G357: 0 | H357: 0 | I357: 0 | J357: 0 | K357: 0 | L357: =SUM(G357:K357) -> 0 | M357: 1 | N357: =G357/M357 -> 0 | O357: 1 | P357: 1 | Q357: 1 | R357: 0 | S357: 0 | T357: -Unknown- | V357: Unknown | X357: Unknown | Z357: =Y357 -> 0 | AA357: =Y357 -> 0 | AC357: 0 | AD357: Unknown | AF357: Unknown | AG357: Unknown | AH357: Unknown | AI357: Unknown | AJ357: Unknown | AK357: Unknown | AL357: Unknown | AM357: Unknown | AN357: Unknown | AO357: Unknown | AP357: Unknown
A358: 356 | E358: -- | G358: 0 | H358: 0 | I358: 0 | J358: 0 | K358: 0 | L358: =SUM(G358:K358) -> 0 | M358: 1 | N358: =G358/M358 -> 0 | O358: 1 | P358: 1 | Q358: 1 | R358: 0 | S358: 0 | T358: -Unknown- | V358: Unknown | X358: Unknown | Z358: =Y358 -> 0 | AA358: =Y358 -> 0 | AC358: 0 | AD358: Unknown | AF358: Unknown | AG358: Unknown | AH358: Unknown | AI358: Unknown | AJ358: Unknown | AK358: Unknown | AL358: Unknown | AM358: Unknown | AN358: Unknown | AO358: Unknown | AP358: Unknown
A359: 357 | E359: -- | G359: 0 | H359: 0 | I359: 0 | J359: 0 | K359: 0 | L359: =SUM(G359:K359) -> 0 | M359: 1 | N359: =G359/M359 -> 0 | O359: 1 | P359: 1 | Q359: 1 | R359: 0 | S359: 0 | T359: -Unknown- | V359: Unknown | X359: Unknown | Z359: =Y359 -> 0 | AA359: =Y359 -> 0 | AC359: 0 | AD359: Unknown | AF359: Unknown | AG359: Unknown | AH359: Unknown | AI359: Unknown | AJ359: Unknown | AK359: Unknown | AL359: Unknown | AM359: Unknown | AN359: Unknown | AO359: Unknown | AP359: Unknown
A360: 358 | E360: -- | G360: 0 | H360: 0 | I360: 0 | J360: 0 | K360: 0 | L360: =SUM(G360:K360) -> 0 | M360: 1 | N360: =G360/M360 -> 0 | O360: 1 | P360: 1 | Q360: 1 | R360: 0 | S360: 0 | T360: -Unknown- | V360: Unknown | X360: Unknown | Z360: =Y360 -> 0 | AA360: =Y360 -> 0 | AC360: 0 | AD360: Unknown | AF360: Unknown | AG360: Unknown | AH360: Unknown | AI360: Unknown | AJ360: Unknown | AK360: Unknown | AL360: Unknown | AM360: Unknown | AN360: Unknown | AO360: Unknown | AP360: Unknown
A361: 359 | E361: -- | G361: 0 | H361: 0 | I361: 0 | J361: 0 | K361: 0 | L361: =SUM(G361:K361) -> 0 | M361: 1 | N361: =G361/M361 -> 0 | O361: 1 | P361: 1 | Q361: 1 | R361: 0 | S361: 0 | T361: -Unknown- | V361: Unknown | X361: Unknown | Z361: =Y361 -> 0 | AA361: =Y361 -> 0 | AC361: 0 | AD361: Unknown | AF361: Unknown | AG361: Unknown | AH361: Unknown | AI361: Unknown | AJ361: Unknown | AK361: Unknown | AL361: Unknown | AM361: Unknown | AN361: Unknown | AO361: Unknown | AP361: Unknown
A362: 360 | E362: -- | G362: 0 | H362: 0 | I362: 0 | J362: 0 | K362: 0 | L362: =SUM(G362:K362) -> 0 | M362: 1 | N362: =G362/M362 -> 0 | O362: 1 | P362: 1 | Q362: 1 | R362: 0 | S362: 0 | T362: -Unknown- | V362: Unknown | X362: Unknown | Z362: =Y362 -> 0 | AA362: =Y362 -> 0 | AC362: 0 | AD362: Unknown | AF362: Unknown | AG362: Unknown | AH362: Unknown | AI362: Unknown | AJ362: Unknown | AK362: Unknown | AL362: Unknown | AM362: Unknown | AN362: Unknown | AO362: Unknown | AP362: Unknown
A363: 361 | E363: -- | G363: 0 | H363: 0 | I363: 0 | J363: 0 | K363: 0 | L363: =SUM(G363:K363) -> 0 | M363: 1 | N363: =G363/M363 -> 0 | O363: 1 | P363: 1 | Q363: 1 | R363: 0 | S363: 0 | T363: -Unknown- | V363: Unknown | X363: Unknown | Z363: =Y363 -> 0 | AA363: =Y363 -> 0 | AC363: 0 | AD363: Unknown | AF363: Unknown | AG363: Unknown | AH363: Unknown | AI363: Unknown | AJ363: Unknown | AK363: Unknown | AL363: Unknown | AM363: Unknown | AN363: Unknown | AO363: Unknown | AP363: Unknown
A364: 362 | E364: -- | G364: 0 | H364: 0 | I364: 0 | J364: 0 | K364: 0 | L364: =SUM(G364:K364) -> 0 | M364: 1 | N364: =G364/M364 -> 0 | O364: 1 | P364: 1 | Q364: 1 | R364: 0 | S364: 0 | T364: -Unknown- | V364: Unknown | X364: Unknown | Z364: =Y364 -> 0 | AA364: =Y364 -> 0 | AC364: 0 | AD364: Unknown | AF364: Unknown | AG364: Unknown | AH364: Unknown | AI364: Unknown | AJ364: Unknown | AK364: Unknown | AL364: Unknown | AM364: Unknown | AN364: Unknown | AO364: Unknown | AP364: Unknown
...

Sheet IV. Loss Information
A3: Loss | B3: Date of Loss | C3: Peril | D3: Loss Description | E3: Paid or Reserved | F3: Status
A4: 1 | C4: Unknown
A5: 2 | C5: Unknown
A6: 3 | C6: Unknown
A7: 4 | C7: Unknown
A8: 5 | C8: Unknown
A9: 6 | C9: Unknown
A10: 7 | C10: Unknown
A11: 8 | C11: Unknown
A12: 9 | C12: Unknown
A13: 10 | C13: Unknown
A14: 11 | C14: Unknown
A15: 12 | C15: Unknown
... A23: 20 | C23: Unknown

Sheet V. Existing Locations
B1: Original Values | G1: Only applies to Renewals/Endorsements to request changing existing values | N1: Values | S1: =SUM(S3:S1000) -> 0 | T1: Total Values Listed
A2: CCLocId | B2: Building | C2: Contents | D2: Business Interuption | E2: Machinery & Equip. | F2: Other | G2: Loc # | H2: Street Address | I2: City | J2: State | K2: Zip | L2: Location Name | M2: Status | N2: Building | O2: Contents | P2: Business Interuption | Q2: Machinery & Equip. | R2: Other | S2: Total
A3: =IF(ExistingImport!A2 = "", "", ExistingImport!A2) | B3: =IF(ExistingImport!B2 = "", "", ExistingImport!B2) | C3: =IF(ExistingImport!C2 = "", "", ExistingImport!C2) | D3: =IF(ExistingImport!D2 = "", "", ExistingImport!D2) | E3: =IF(ExistingImport!E2 = "", "", ExistingImport!E2) | F3: =IF(ExistingImport!F2 = "", "", ExistingImport!F2) | G3: =IF(ExistingImport!A2 = "", "", ExistingImport!A2) | H3: =IF(ExistingImport!G2 = "", "", ExistingImport!G2) | I3: =IF(ExistingImport!H2 = "", "", ExistingImport!H2) | J3: =IF(ExistingImport!I2 = "", "", ExistingImport!I2) | K3: =IF(ExistingImport!J2 = "", "", ExistingImport!J2) | L3: =IF(ExistingImport!K2 = "", "", ExistingImport!K2) | M3: Current | N3: =B3 | O3: =C3 | P3: =D3 | Q3: =E3 | R3: =F3 | S3: =SUM(N3:R3) -> 0
A4: =IF(ExistingImport!A3 = "", "", ExistingImport!A3) | B4: =IF(ExistingImport!B3 = "", "", ExistingImport!B3) | C4: =IF(ExistingImport!C3 = "", "", ExistingImport!C3) | D4: =IF(ExistingImport!D3 = "", "", ExistingImport!D3) | E4: =IF(ExistingImport!E3 = "", "", ExistingImport!E3) | F4: =IF(ExistingImport!F3 = "", "", ExistingImport!F3) | G4: =IF(ExistingImport!A3 = "", "", ExistingImport!A3) | H4: =IF(ExistingImport!G3 = "", "", ExistingImport!G3) | I4: =IF(ExistingImport!H3 = "", "", ExistingImport!H3) | J4: =IF(ExistingImport!I3 = "", "", ExistingImport!I3) | K4: =IF(ExistingImport!J3 = "", "", ExistingImport!J3) | L4: =IF(ExistingImport!K3 = "", "", ExistingImport!K3) | M4: =IF(ExistingImport!L3 = "", "", ExistingImport!L3) | N4: =B4 | O4: =C4 | P4: =D4 | Q4: =E4 | R4: =F4 | S4: =SUM(N4:R4) -> 0
A5: =IF(ExistingImport!A4 = "", "", ExistingImport!A4) | B5: =IF(ExistingImport!B4 = "", "", ExistingImport!B4) | C5: =IF(ExistingImport!C4 = "", "", ExistingImport!C4) | D5: =IF(ExistingImport!D4 = "", "", ExistingImport!D4) | E5: =IF(ExistingImport!E4 = "", "", ExistingImport!E4) | F5: =IF(ExistingImport!F4 = "", "", ExistingImport!F4) | G5: =IF(ExistingImport!A4 = "", "", ExistingImport!A4) | H5: =IF(ExistingImport!G4 = "", "", ExistingImport!G4) | I5: =IF(ExistingImport!H4 = "", "", ExistingImport!H4) | J5: =IF(ExistingImport!I4 = "", "", ExistingImport!I4) | K5: =IF(ExistingImport!J4 = "", "", ExistingImport!J4) | L5: =IF(ExistingImport!K4 = "", "", ExistingImport!K4) | M5: =IF(ExistingImport!L4 = "", "", ExistingImport!L4) | N5: =B5 | O5: =C5 | P5: =D5 | Q5: =E5 | R5: =F5 | S5: =SUM(N5:R5) -> 0
A6: =IF(ExistingImport!A5 = "", "", ExistingImport!A5) | B6: =IF(ExistingImport!B5 = "", "", ExistingImport!B5) | C6: =IF(ExistingImport!C5 = "", "", ExistingImport!C5) | D6: =IF(ExistingImport!D5 = "", "", ExistingImport!D5) | E6: =IF(ExistingImport!E5 = "", "", ExistingImport!E5) | F6: =IF(ExistingImport!F5 = "", "", ExistingImport!F5) | G6: =IF(ExistingImport!A5 = "", "", ExistingImport!A5) | H6: =IF(ExistingImport!G5 = "", "", ExistingImport!G5) | I6: =IF(ExistingImport!H5 = "", "", ExistingImport!H5) | J6: =IF(ExistingImport!I5 = "", "", ExistingImport!I5) | K6: =IF(ExistingImport!J5 = "", "", ExistingImport!J5) | L6: =IF(ExistingImport!K5 = "", "", ExistingImport!K5) | M6: =IF(ExistingImport!L5 = "", "", ExistingImport!L5) | N6: =B6 | O6: =C6 | P6: =D6 | Q6: =E6 | R6: =F6 | S6: =SUM(N6:R6) -> 0
A7: =IF(ExistingImport!A6 = "", "", ExistingImport!A6) | B7: =IF(ExistingImport!B6 = "", "", ExistingImport!B6) | C7: =IF(ExistingImport!C6 = "", "", ExistingImport!C6) | D7: =IF(ExistingImport!D6 = "", "", ExistingImport!D6) | E7: =IF(ExistingImport!E6 = "", "", ExistingImport!E6) | F7: =IF(ExistingImport!F6 = "", "", ExistingImport!F6) | G7: =IF(ExistingImport!A6 = "", "", ExistingImport!A6) | H7: =IF(ExistingImport!G6 = "", "", ExistingImport!G6) | I7: =IF(ExistingImport!H6 = "", "", ExistingImport!H6) | J7: =IF(ExistingImport!I6 = "", "", ExistingImport!I6) | K7: =IF(ExistingImport!J6 = "", "", ExistingImport!J6) | L7: =IF(ExistingImport!K6 = "", "", ExistingImport!K6) | M7: =IF(ExistingImport!L6 = "", "", ExistingImport!L6) | N7: =B7 | O7: =C7 | P7: =D7 | Q7: =E7 | R7: =F7 | S7: =SUM(N7:R7) -> 0
A8: =IF(ExistingImport!A7 = "", "", ExistingImport!A7) | B8: =IF(ExistingImport!B7 = "", "", ExistingImport!B7) | C8: =IF(ExistingImport!C7 = "", "", ExistingImport!C7) | D8: =IF(ExistingImport!D7 = "", "", ExistingImport!D7) | E8: =IF(ExistingImport!E7 = "", "", ExistingImport!E7) | F8: =IF(ExistingImport!F7 = "", "", ExistingImport!F7) | G8: =IF(ExistingImport!A7 = "", "", ExistingImport!A7) | H8: =IF(ExistingImport!G7 = "", "", ExistingImport!G7) | I8: =IF(ExistingImport!H7 = "", "", ExistingImport!H7) | J8: =IF(ExistingImport!I7 = "", "", ExistingImport!I7) | K8: =IF(ExistingImport!J7 = "", "", ExistingImport!J7) | L8: =IF(ExistingImport!K7 = "", "", ExistingImport!K7) | M8: =IF(ExistingImport!L7 = "", "", ExistingImport!L7) | N8: =B8 | O8: =C8 | P8: =D8 | Q8: =E8 | R8: =F8 | S8: =SUM(N8:R8) -> 0
A9: =IF(ExistingImport!A8 = "", "", ExistingImport!A8) | B9: =IF(ExistingImport!B8 = "", "", ExistingImport!B8) | C9: =IF(ExistingImport!C8 = "", "", ExistingImport!C8) | D9: =IF(ExistingImport!D8 = "", "", ExistingImport!D8) | E9: =IF(ExistingImport!E8 = "", "", ExistingImport!E8) | F9: =IF(ExistingImport!F8 = "", "", ExistingImport!F8) | G9: =IF(ExistingImport!A8 = "", "", ExistingImport!A8) | H9: =IF(ExistingImport!G8 = "", "", ExistingImport!G8) | I9: =IF(ExistingImport!H8 = "", "", ExistingImport!H8) | J9: =IF(ExistingImport!I8 = "", "", ExistingImport!I8) | K9: =IF(ExistingImport!J8 = "", "", ExistingImport!J8) | L9: =IF(ExistingImport!K8 = "", "", ExistingImport!K8) | M9: =IF(ExistingImport!L8 = "", "", ExistingImport!L8) | N9: =B9 | O9: =C9 | P9: =D9 | Q9: =E9 | R9: =F9 | S9: =SUM(N9:R9) -> 0
A10: =IF(ExistingImport!A9 = "", "", ExistingImport!A9) | B10: =IF(ExistingImport!B9 = "", "", ExistingImport!B9) | C10: =IF(ExistingImport!C9 = "", "", ExistingImport!C9) | D10: =IF(ExistingImport!D9 = "", "", ExistingImport!D9) | E10: =IF(ExistingImport!E9 = "", "", ExistingImport!E9) | F10: =IF(ExistingImport!F9 = "", "", ExistingImport!F9) | G10: =IF(ExistingImport!A9 = "", "", ExistingImport!A9) | H10: =IF(ExistingImport!G9 = "", "", ExistingImport!G9) | I10: =IF(ExistingImport!H9 = "", "", ExistingImport!H9) | J10: =IF(ExistingImport!I9 = "", "", ExistingImport!I9) | K10: =IF(ExistingImport!J9 = "", "", ExistingImport!J9) | L10: =IF(ExistingImport!K9 = "", "", ExistingImport!K9) | M10: =IF(ExistingImport!L9 = "", "", ExistingImport!L9) | N10: =B10 | O10: =C10 | P10: =D10 | Q10: =E10 | R10: =F10 | S10: =SUM(N10:R10) -> 0
A11: =IF(ExistingImport!A10 = "", "", ExistingImport!A10) | B11: =IF(ExistingImport!B10 = "", "", ExistingImport!B10) | C11: =IF(ExistingImport!C10 = "", "", ExistingImport!C10) | D11: =IF(ExistingImport!D10 = "", "", ExistingImport!D10) | E11: =IF(ExistingImport!E10 = "", "", ExistingImport!E10) | F11: =IF(ExistingImport!F10 = "", "", ExistingImport!F10) | G11: =IF(ExistingImport!A10 = "", "", ExistingImport!A10) | H11: =IF(ExistingImport!G10 = "", "", ExistingImport!G10) | I11: =IF(ExistingImport!H10 = "", "", ExistingImport!H10) | J11: =IF(ExistingImport!I10 = "", "", ExistingImport!I10) | K11: =IF(ExistingImport!J10 = "", "", ExistingImport!J10) | L11: =IF(ExistingImport!K10 = "", "", ExistingImport!K10) | M11: =IF(ExistingImport!L10 = "", "", ExistingImport!L10) | N11: =B11 | O11: =C11 | P11: =D11 | Q11: =E11 | R11: =F11 | S11: =SUM(N11:R11) -> 0
A12: =IF(ExistingImport!A11 = "", "", ExistingImport!A11) | B12: =IF(ExistingImport!B11 = "", "", ExistingImport!B11) | C12: =IF(ExistingImport!C11 = "", "", ExistingImport!C11) | D12: =IF(ExistingImport!D11 = "", "", ExistingImport!D11) | E12: =IF(ExistingImport!E11 = "", "", ExistingImport!E11) | F12: =IF(ExistingImport!F11 = "", "", ExistingImport!F11) | G12: =IF(ExistingImport!A11 = "", "", ExistingImport!A11) | H12: =IF(ExistingImport!G11 = "", "", ExistingImport!G11) | I12: =IF(ExistingImport!H11 = "", "", ExistingImport!H11) | J12: =IF(ExistingImport!I11 = "", "", ExistingImport!I11) | K12: =IF(ExistingImport!J11 = "", "", ExistingImport!J11) | L12: =IF(ExistingImport!K11 = "", "", ExistingImport!K11) | M12: =IF(ExistingImport!L11 = "", "", ExistingImport!L11) | N12: =B12 | O12: =C12 | P12: =D12 | Q12: =E12 | R12: =F12 | S12: =SUM(N12:R12) -> 0
A13: =IF(ExistingImport!A12 = "", "", ExistingImport!A12) | B13: =IF(ExistingImport!B12 = "", "", ExistingImport!B12) | C13: =IF(ExistingImport!C12 = "", "", ExistingImport!C12) | D13: =IF(ExistingImport!D12 = "", "", ExistingImport!D12) | E13: =IF(ExistingImport!E12 = "", "", ExistingImport!E12) | F13: =IF(ExistingImport!F12 = "", "", ExistingImport!F12) | G13: =IF(ExistingImport!A12 = "", "", ExistingImport!A12) | H13: =IF(ExistingImport!G12 = "", "", ExistingImport!G12) | I13: =IF(ExistingImport!H12 = "", "", ExistingImport!H12) | J13: =IF(ExistingImport!I12 = "", "", ExistingImport!I12) | K13: =IF(ExistingImport!J12 = "", "", ExistingImport!J12) | L13: =IF(ExistingImport!K12 = "", "", ExistingImport!K12) | M13: =IF(ExistingImport!L12 = "", "", ExistingImport!L12) | N13: =B13 | O13: =C13 | P13: =D13 | Q13: =E13 | R13: =F13 | S13: =SUM(N13:R13) -> 0
A14: =IF(ExistingImport!A13 = "", "", ExistingImport!A13) | B14: =IF(ExistingImport!B13 = "", "", ExistingImport!B13) | C14: =IF(ExistingImport!C13 = "", "", ExistingImport!C13) | D14: =IF(ExistingImport!D13 = "", "", ExistingImport!D13) | E14: =IF(ExistingImport!E13 = "", "", ExistingImport!E13) | F14: =IF(ExistingImport!F13 = "", "", ExistingImport!F13) | G14: =IF(ExistingImport!A13 = "", "", ExistingImport!A13) | H14: =IF(ExistingImport!G13 = "", "", ExistingImport!G13) | I14: =IF(ExistingImport!H13 = "", "", ExistingImport!H13) | J14: =IF(ExistingImport!I13 = "", "", ExistingImport!I13) | K14: =IF(ExistingImport!J13 = "", "", ExistingImport!J13) | L14: =IF(ExistingImport!K13 = "", "", ExistingImport!K13) | M14: =IF(ExistingImport!L13 = "", "", ExistingImport!L13) | N14: =B14 | O14: =C14 | P14: =D14 | Q14: =E14 | R14: =F14 | S14: =SUM(N14:R14) -> 0
A15: =IF(ExistingImport!A14 = "", "", ExistingImport!A14) | B15: =IF(ExistingImport!B14 = "", "", ExistingImport!B14) | C15: =IF(ExistingImport!C14 = "", "", ExistingImport!C14) | D15: =IF(ExistingImport!D14 = "", "", ExistingImport!D14) | E15: =IF(ExistingImport!E14 = "", "", ExistingImport!E14) | F15: =IF(ExistingImport!F14 = "", "", ExistingImport!F14) | G15: =IF(ExistingImport!A14 = "", "", ExistingImport!A14) | H15: =IF(ExistingImport!G14 = "", "", ExistingImport!G14) | I15: =IF(ExistingImport!H14 = "", "", ExistingImport!H14) | J15: =IF(ExistingImport!I14 = "", "", ExistingImport!I14) | K15: =IF(ExistingImport!J14 = "", "", ExistingImport!J14) | L15: =IF(ExistingImport!K14 = "", "", ExistingImport!K14) | M15: =IF(ExistingImport!L14 = "", "", ExistingImport!L14) | N15: =B15 | O15: =C15 | P15: =D15 | Q15: =E15 | R15: =F15 | S15: =SUM(N15:R15) -> 0
... A528: =IF(ExistingImport!A527 = "", "", ExistingImport!A527) | B528: =IF(ExistingImport!B527 = "", "", ExistingImport!B527) | C528: =IF(ExistingImport!C527 = "", "", ExistingImport!C527) | D528: =IF(ExistingImport!D527 = "", "", ExistingImport!D527) | E528: =IF(ExistingImport!E527 = "", "", ExistingImport!E527) | F528: =IF(ExistingImport!F527 = "", "", ExistingImport!F527) | G528: =IF(ExistingImport!A527 = "", "", ExistingImport!A527) | H528: =IF(ExistingImport!G527 = "", "", ExistingImport!G527) | I528: =IF(ExistingImport!H527 = "", "", ExistingImport!H527) | J528: =IF(ExistingImport!I527 = "", "", ExistingImport!I527) | K528: =IF(ExistingImport!J527 = "", "", ExistingImport!J527) | L528: =IF(ExistingImport!K527 = "", "", ExistingImport!K527) | M528: =IF(ExistingImport!L527 = "", "", ExistingImport!L527) | N528: =B528 | O528: =C528 | P528: =D528 | Q528: =E528 | R528: =F528 | S528: =SUM(N528:R528) -> 0

Sheet Valid1
E1: =SUM(E4:E2002) -> 0 | F1: =SUM(F4:F2002) -> 0 | G1: =SUM(G4:G2002) -> 0 | H1: =SUM(H4:H2002) -> 0 | I1: =SUM(I4:I2002) -> 0 | J1: =SUM(J4:J2002) -> 0 | K1: =SUM(K4:K2002) -> 0 | M1: =SUM(M4:M2002) -> 0 | O1: =SUM(O4:O2002) -> 0 | P1: =SUM(P4:P2002) -> 0 | Q1: =SUM(Q4:Q2002) -> 0 | R1: =SUM(R4:R2002) -> 0 | S1: =SUM(S4:S2002) -> 0 | U1: =SUM(U4:U2002) -> 0 | W1: =SUM(W4:W2002) -> 0 | Y1: =SUM(Y4:Y2002) -> 0 | Z1: =SUM(Z4:Z2002) -> 0 | AA1: =SUM(AA4:AA2002) -> 0 | AC1: =SUM(AC4:AC2002) -> 0
C2: used for false value | E2: 2 digit | F2: zip | G2: number | H2: number | I2: number | J2: number | K2: number | M2: number | O2: number | P2: number | Q2: number | R2: percentage | S2: percentage | T2: one of these 2 are required | V2: one of these 2 are required | Y2: year | Z2: year | AA2: year | AC2: percentage
A3: ='III. New Locations'!A2 -> New Loc # | B3: ='III. New Locations'!B2 -> Location Name | C3: ='III. New Locations'!C2 -> Street Address | D3: ='III. New Locations'!D2 -> City | E3: ='III. New Locations'!E2 -> State | F3: ='III. New Locations'!F2 -> Zip | G3: ='III. New Locations'!G2 -> Building | H3: ='III. New Locations'!H2 -> Contents | ... AP3: ='III. New Locations'!AP2 -> Cladding Type
A4: ='III. New Locations'!A3 -> 1 | C4: =IF(LEN('III. New Locations'!C3) > 2, 1, 0) -> 0 | E4: =IF(LEN('III. New Locations'!E3) = 2, IF('III. New Locations'!E3 = "--", $C4, 0), $C4) -> 0 | F4: =IF(LEN('III. New Locations'!F3) > 3, 0, $C4) -> 0 | G4: =IF(ISNUMBER('III. New Locations'!G3) = TRUE, 0, $C4) -> 0 | H4: =IF(ISNUMBER('III. New Locations'!H3) = TRUE, 0, $C4) -> 0 | I4: =IF(ISNUMBER('III. New Locations'!I3) = TRUE, 0, $C4) -> 0 | J4: =IF(ISNUMBER('III. New Locations'!J3) = TRUE, 0, $C4) -> 0 | K4: =IF(ISNUMBER('III. New Locations'!K3) = TRUE, 0,$C4) -> 0 | M4: =IF(ISNUMBER('III. New Locations'!M3) = TRUE, 0,$C4) -> 0 | O4: =IF(ISNUMBER('III. New Locations'!O3) = TRUE, 0, $C4) -> 0 | P4: =IF(ISNUMBER('III. New Locations'!P3) = TRUE, 0, $C4) -> 0 | Q4: =IF(ISNUMBER('III. New Locations'!Q3) = TRUE, 0, $C4) -> 0 | R4: =IF(ISNUMBER('III. New Locations'!R3) = TRUE, IF('III. New Locations'!R3 >= 0, IF('III. New Locations'!R3 <=1, 0, $C4),$C4),$C4) -> 0 | S4: =IF(ISNUMBER('III. New Locations'!S3) = TRUE, IF('III. New Locations'!S3 >= 0, IF('III. New Locations'!S3 <=1, 0, $C4), $C4), $C4) -> 0 | T4: =IF('III. New Locations'!T3 = "-Unknown-", $C4, 0) -> 0 | U4: =IF(LEN('III. New Locations'!U3)>1, 0, IF(T4 = 0, 0, $C4)) -> 0 | V4: =IF('III. New Locations'!V3 = "Unknown", $C4, 0) -> 0 | W4: =IF(LEN('III. New Locations'!W3)>1, 0, IF(V4 = 0, 0, $C4)) -> 0 | X4: ='III. New Locations'!X3 -> 0 | Y4: =IF(ISNUMBER('III. New Locations'!Y3) = TRUE, IF('III. New Locations'!Y3 >= 1400, IF('III. New Locations'!Y3 <=2100, 0, $C4), $C4), $C4) -> 0 | Z4: =IF(ISNUMBER('III. New Locations'!Z3) = TRUE, IF('III. New Locations'!Z3 >= 1400, IF('III. New Locations'!Z3 <=2100, 0, $C4), $C4), $C4) -> 0 | AA4: =IF(ISNUMBER('III. New Locations'!AA3) = TRUE, IF('III. New Locations'!AA3 >= 1400, IF('III. New Locations'!AA3 <=2100, 0, $C4), $C4), $C4) -> 0 | AC4: =IF(ISNUMBER('III. New Locations'!AC3) = TRUE, IF('III. New Locations'!AC3 >= 0, IF('III. New Locations'!AC3 <=1, 0,$C4),$C4), $C4) -> 0
A5: ='III. New Locations'!A4 -> 2 | C5: =IF(LEN('III. New Locations'!C4) > 2, 1, 0) -> 0 | E5: =IF(LEN('III. New Locations'!E4) = 2, IF('III. New Locations'!E4 = "--", $C5, 0), $C5) -> 0 | F5: =IF(LEN('III. New Locations'!F4) > 4, 0, $C5) -> 0 | G5: =IF(ISNUMBER('III. New Locations'!G4) = TRUE, 0, $C5) -> 0 | H5: =IF(ISNUMBER('III. New Locations'!H4) = TRUE, 0, $C5) -> 0 | I5: =IF(ISNUMBER('III. New Locations'!I4) = TRUE, 0, $C5) -> 0 | J5: =IF(ISNUMBER('III. New Locations'!J4) = TRUE, 0, $C5) -> 0 | K5: =IF(ISNUMBER('III. New Locations'!K4) = TRUE, 0,$C5) -> 0 | M5: =IF(ISNUMBER('III. New Locations'!M4) = TRUE, 0,$C5) -> 0 | O5: =IF(ISNUMBER('III. New Locations'!O4) = TRUE, 0, $C5) -> 0 | P5: =IF(ISNUMBER('III. New Locations'!P4) = TRUE, 0, $C5) -> 0 | Q5: =IF(ISNUMBER('III. New Locations'!Q4) = TRUE, 0, $C5) -> 0 | R5: =IF(ISNUMBER('III. New Locations'!R4) = TRUE, IF('III. New Locations'!R4 >= 0, IF('III. New Locations'!R4 <=1, 0, $C5),$C5),$C5) -> 0 | S5: =IF(ISNUMBER('III. New Locations'!S4) = TRUE, IF('III. New Locations'!S4 >= 0, IF('III. New Locations'!S4 <=1, 0, $C5), $C5), $C5) -> 0 | T5: =IF('III. New Locations'!T4 = "-Unknown-", $C5, 0) -> 0 | U5: =IF(LEN('III. New Locations'!U4)>1, 0, IF(T5 = 0, 0, $C5)) -> 0 | V5: =IF('III. New Locations'!V4 = "Unknown", $C5, 0) -> 0 | W5: =IF(LEN('III. New Locations'!W4)>1, 0, IF(V5 = 0, 0, $C5)) -> 0 | X5: ='III. New Locations'!X4 -> 0 | Y5: =IF(ISNUMBER('III. New Locations'!Y4) = TRUE, IF('III. New Locations'!Y4 >= 1400, IF('III. New Locations'!Y4 <=2100, 0, $C5), $C5), $C5) -> 0 | Z5: =IF(ISNUMBER('III. New Locations'!Z4) = TRUE, IF('III. New Locations'!Z4 >= 1400, IF('III. New Locations'!Z4 <=2100, 0, $C5), $C5), $C5) -> 0 | AA5: =IF(ISNUMBER('III. New Locations'!AA4) = TRUE, IF('III. New Locations'!AA4 >= 1400, IF('III. New Locations'!AA4 <=2100, 0, $C5), $C5), $C5) -> 0 | AC5: =IF(ISNUMBER('III. New Locations'!AC4) = TRUE, IF('III. New Locations'!AC4 >= 0, IF('III. New Locations'!AC4 <=1, 0,$C5),$C5), $C5) -> 0
A6: ='III. New Locations'!A5 -> 3 | C6: =IF(LEN('III. New Locations'!C5) > 2, 1, 0) -> 0 | E6: =IF(LEN('III. New Locations'!E5) = 2, IF('III. New Locations'!E5 = "--", $C6, 0), $C6) -> 0 | F6: =IF(LEN('III. New Locations'!F5) > 4, 0, $C6) -> 0 | G6: =IF(ISNUMBER('III. New Locations'!G5) = TRUE, 0, $C6) -> 0 | H6: =IF(ISNUMBER('III. New Locations'!H5) = TRUE, 0, $C6) -> 0 | I6: =IF(ISNUMBER('III. New Locations'!I5) = TRUE, 0, $C6) -> 0 | J6: =IF(ISNUMBER('III. New Locations'!J5) = TRUE, 0, $C6) -> 0 | K6: =IF(ISNUMBER('III. New Locations'!K5) = TRUE, 0,$C6) -> 0 | M6: =IF(ISNUMBER('III. New Locations'!M5) = TRUE, 0,$C6) -> 0 | O6: =IF(ISNUMBER('III. New Locations'!O5) = TRUE, 0, $C6) -> 0 | P6: =IF(ISNUMBER('III. New Locations'!P5) = TRUE, 0, $C6) -> 0 | Q6: =IF(ISNUMBER('III. New Locations'!Q5) = TRUE, 0, $C6) -> 0 | R6: =IF(ISNUMBER('III. New Locations'!R5) = TRUE, IF('III. New Locations'!R5 >= 0, IF('III. New Locations'!R5 <=1, 0, $C6),$C6),$C6) -> 0 | S6: =IF(ISNUMBER('III. New Locations'!S5) = TRUE, IF('III. New Locations'!S5 >= 0, IF('III. New Locations'!S5 <=1, 0, $C6), $C6), $C6) -> 0 | T6: =IF('III. New Locations'!T5 = "-Unknown-", $C6, 0) -> 0 | U6: =IF(LEN('III. New Locations'!U5)>1, 0, IF(T6 = 0, 0, $C6)) -> 0 | V6: =IF('III. New Locations'!V5 = "Unknown", $C6, 0) -> 0 | W6: =IF(LEN('III. New Locations'!W5)>1, 0, IF(V6 = 0, 0, $C6)) -> 0 | X6: ='III. New Locations'!X5 -> 0 | Y6: =IF(ISNUMBER('III. New Locations'!Y5) = TRUE, IF('III. New Locations'!Y5 >= 1400, IF('III. New Locations'!Y5 <=2100, 0, $C6), $C6), $C6) -> 0 | Z6: =IF(ISNUMBER('III. New Locations'!Z5) = TRUE, IF('III. New Locations'!Z5 >= 1400, IF('III. New Locations'!Z5 <=2100, 0, $C6), $C6), $C6) -> 0 | AA6: =IF(ISNUMBER('III. New Locations'!AA5) = TRUE, IF('III. New Locations'!AA5 >= 1400, IF('III. New Locations'!AA5 <=2100, 0, $C6), $C6), $C6) -> 0 | AC6: =IF(ISNUMBER('III. New Locations'!AC5) = TRUE, IF('III. New Locations'!AC5 >= 0, IF('III. New Locations'!AC5 <=1, 0,$C6),$C6), $C6) -> 0
A7: ='III. New Locations'!A6 -> 4 | C7: =IF(LEN('III. New Locations'!C6) > 2, 1, 0) -> 0 | E7: =IF(LEN('III. New Locations'!E6) = 2, IF('III. New Locations'!E6 = "--", $C7, 0), $C7) -> 0 | F7: =IF(LEN('III. New Locations'!F6) > 4, 0, $C7) -> 0 | G7: =IF(ISNUMBER('III. New Locations'!G6) = TRUE, 0, $C7) -> 0 | H7: =IF(ISNUMBER('III. New Locations'!H6) = TRUE, 0, $C7) -> 0 | I7: =IF(ISNUMBER('III. New Locations'!I6) = TRUE, 0, $C7) -> 0 | J7: =IF(ISNUMBER('III. New Locations'!J6) = TRUE, 0, $C7) -> 0 | K7: =IF(ISNUMBER('III. New Locations'!K6) = TRUE, 0,$C7) -> 0 | M7: =IF(ISNUMBER('III. New Locations'!M6) = TRUE, 0,$C7) -> 0 | O7: =IF(ISNUMBER('III. New Locations'!O6) = TRUE, 0, $C7) -> 0 | P7: =IF(ISNUMBER('III. New Locations'!P6) = TRUE, 0, $C7) -> 0 | Q7: =IF(ISNUMBER('III. New Locations'!Q6) = TRUE, 0, $C7) -> 0 | R7: =IF(ISNUMBER('III. New Locations'!R6) = TRUE, IF('III. New Locations'!R6 >= 0, IF('III. New Locations'!R6 <=1, 0, $C7),$C7),$C7) -> 0 | S7: =IF(ISNUMBER('III. New Locations'!S6) = TRUE, IF('III. New Locations'!S6 >= 0, IF('III. New Locations'!S6 <=1, 0, $C7), $C7), $C7) -> 0 | T7: =IF('III. New Locations'!T6 = "-Unknown-", $C7, 0) -> 0 | U7: =IF(LEN('III. New Locations'!U6)>1, 0, IF(T7 = 0, 0, $C7)) -> 0 | V7: =IF('III. New Locations'!V6 = "Unknown", $C7, 0) -> 0 | W7: =IF(LEN('III. New Locations'!W6)>1, 0, IF(V7 = 0, 0, $C7)) -> 0 | X7: ='III. New Locations'!X6 -> 0 | Y7: =IF(ISNUMBER('III. New Locations'!Y6) = TRUE, IF('III. New Locations'!Y6 >= 1400, IF('III. New Locations'!Y6 <=2100, 0, $C7), $C7), $C7) -> 0 | Z7: =IF(ISNUMBER('III. New Locations'!Z6) = TRUE, IF('III. New Locations'!Z6 >= 1400, IF('III. New Locations'!Z6 <=2100, 0, $C7), $C7), $C7) -> 0 | AA7: =IF(ISNUMBER('III. New Locations'!AA6) = TRUE, IF('III. New Locations'!AA6 >= 1400, IF('III. New Locations'!AA6 <=2100, 0, $C7), $C7), $C7) -> 0 | AC7: =IF(ISNUMBER('III. New Locations'!AC6) = TRUE, IF('III. New Locations'!AC6 >= 0, IF('III. New Locations'!AC6 <=1, 0,$C7),$C7), $C7) -> 0
A8: ='III. New Locations'!A7 -> 5 | C8: =IF(LEN('III. New Locations'!C7) > 2, 1, 0) -> 0 | E8: =IF(LEN('III. New Locations'!E7) = 2, IF('III. New Locations'!E7 = "--", $C8, 0), $C8) -> 0 | F8: =IF(LEN('III. New Locations'!F7) > 4, 0, $C8) -> 0 | G8: =IF(ISNUMBER('III. New Locations'!G7) = TRUE, 0, $C8) -> 0 | H8: =IF(ISNUMBER('III. New Locations'!H7) = TRUE, 0, $C8) -> 0 | I8: =IF(ISNUMBER('III. New Locations'!I7) = TRUE, 0, $C8) -> 0 | J8: =IF(ISNUMBER('III. New Locations'!J7) = TRUE, 0, $C8) -> 0 | K8: =IF(ISNUMBER('III. New Locations'!K7) = TRUE, 0,$C8) -> 0 | M8: =IF(ISNUMBER('III. New Locations'!M7) = TRUE, 0,$C8) -> 0 | O8: =IF(ISNUMBER('III. New Locations'!O7) = TRUE, 0, $C8) -> 0 | P8: =IF(ISNUMBER('III. New Locations'!P7) = TRUE, 0, $C8) -> 0 | Q8: =IF(ISNUMBER('III. New Locations'!Q7) = TRUE, 0, $C8) -> 0 | R8: =IF(ISNUMBER('III. New Locations'!R7) = TRUE, IF('III. New Locations'!R7 >= 0, IF('III. New Locations'!R7 <=1, 0, $C8),$C8),$C8) -> 0 | S8: =IF(ISNUMBER('III. New Locations'!S7) = TRUE, IF('III. New Locations'!S7 >= 0, IF('III. New Locations'!S7 <=1, 0, $C8), $C8), $C8) -> 0 | T8: =IF('III. New Locations'!T7 = "-Unknown-", $C8, 0) -> 0 | U8: =IF(LEN('III. New Locations'!U7)>1, 0, IF(T8 = 0, 0, $C8)) -> 0 | V8: =IF('III. New Locations'!V7 = "Unknown", $C8, 0) -> 0 | W8: =IF(LEN('III. New Locations'!W7)>1, 0, IF(V8 = 0, 0, $C8)) -> 0 | X8: ='III. New Locations'!X7 -> 0 | Y8: =IF(ISNUMBER('III. New Locations'!Y7) = TRUE, IF('III. New Locations'!Y7 >= 1400, IF('III. New Locations'!Y7 <=2100, 0, $C8), $C8), $C8) -> 0 | Z8: =IF(ISNUMBER('III. New Locations'!Z7) = TRUE, IF('III. New Locations'!Z7 >= 1400, IF('III. New Locations'!Z7 <=2100, 0, $C8), $C8), $C8) -> 0 | AA8: =IF(ISNUMBER('III. New Locations'!AA7) = TRUE, IF('III. New Locations'!AA7 >= 1400, IF('III. New Locations'!AA7 <=2100, 0, $C8), $C8), $C8) -> 0 | AC8: =IF(ISNUMBER('III. New Locations'!AC7) = TRUE, IF('III. New Locations'!AC7 >= 0, IF('III. New Locations'!AC7 <=1, 0,$C8),$C8), $C8) -> 0
A9: ='III. New Locations'!A8 -> 6 | C9: =IF(LEN('III. New Locations'!C8) > 2, 1, 0) -> 0 | E9: =IF(LEN('III. New Locations'!E8) = 2, IF('III. New Locations'!E8 = "--", $C9, 0), $C9) -> 0 | F9: =IF(LEN('III. New Locations'!F8) > 4, 0, $C9) -> 0 | G9: =IF(ISNUMBER('III. New Locations'!G8) = TRUE, 0, $C9) -> 0 | H9: =IF(ISNUMBER('III. New Locations'!H8) = TRUE, 0, $C9) -> 0 | I9: =IF(ISNUMBER('III. New Locations'!I8) = TRUE, 0, $C9) -> 0 | J9: =IF(ISNUMBER('III. New Locations'!J8) = TRUE, 0, $C9) -> 0 | K9: =IF(ISNUMBER('III. New Locations'!K8) = TRUE, 0,$C9) -> 0 | M9: =IF(ISNUMBER('III. New Locations'!M8) = TRUE, 0,$C9) -> 0 | O9: =IF(ISNUMBER('III. New Locations'!O8) = TRUE, 0, $C9) -> 0 | P9: =IF(ISNUMBER('III. New Locations'!P8) = TRUE, 0, $C9) -> 0 | Q9: =IF(ISNUMBER('III. New Locations'!Q8) = TRUE, 0, $C9) -> 0 | R9: =IF(ISNUMBER('III. New Locations'!R8) = TRUE, IF('III. New Locations'!R8 >= 0, IF('III. New Locations'!R8 <=1, 0, $C9),$C9),$C9) -> 0 | S9: =IF(ISNUMBER('III. New Locations'!S8) = TRUE, IF('III. New Locations'!S8 >= 0, IF('III. New Locations'!S8 <=1, 0, $C9), $C9), $C9) -> 0 | T9: =IF('III. New Locations'!T8 = "-Unknown-", $C9, 0) -> 0 | U9: =IF(LEN('III. New Locations'!U8)>1, 0, IF(T9 = 0, 0, $C9)) -> 0 | V9: =IF('III. New Locations'!V8 = "Unknown", $C9, 0) -> 0 | W9: =IF(LEN('III. New Locations'!W8)>1, 0, IF(V9 = 0, 0, $C9)) -> 0 | X9: ='III. New Locations'!X8 -> 0 | Y9: =IF(ISNUMBER('III. New Locations'!Y8) = TRUE, IF('III. New Locations'!Y8 >= 1400, IF('III. New Locations'!Y8 <=2100, 0, $C9), $C9), $C9) -> 0 | Z9: =IF(ISNUMBER('III. New Locations'!Z8) = TRUE, IF('III. New Locations'!Z8 >= 1400, IF('III. New Locations'!Z8 <=2100, 0, $C9), $C9), $C9) -> 0 | AA9: =IF(ISNUMBER('III. New Locations'!AA8) = TRUE, IF('III. New Locations'!AA8 >= 1400, IF('III. New Locations'!AA8 <=2100, 0, $C9), $C9), $C9) -> 0 | AC9: =IF(ISNUMBER('III. New Locations'!AC8) = TRUE, IF('III. New Locations'!AC8 >= 0, IF('III. New Locations'!AC8 <=1, 0,$C9),$C9), $C9) -> 0
A10: ='III. New Locations'!A9 -> 7 | C10: =IF(LEN('III. New Locations'!C9) > 2, 1, 0) -> 0 | E10: =IF(LEN('III. New Locations'!E9) = 2, IF('III. New Locations'!E9 = "--", $C10, 0), $C10) -> 0 | F10: =IF(LEN('III. New Locations'!F9) > 4, 0, $C10) -> 0 | G10: =IF(ISNUMBER('III. New Locations'!G9) = TRUE, 0, $C10) -> 0 | H10: =IF(ISNUMBER('III. New Locations'!H9) = TRUE, 0, $C10) -> 0 | I10: =IF(ISNUMBER('III. New Locations'!I9) = TRUE, 0, $C10) -> 0 | J10: =IF(ISNUMBER('III. New Locations'!J9) = TRUE, 0, $C10) -> 0 | K10: =IF(ISNUMBER('III. New Locations'!K9) = TRUE, 0,$C10) -> 0 | M10: =IF(ISNUMBER('III. New Locations'!M9) = TRUE, 0,$C10) -> 0 | O10: =IF(ISNUMBER('III. New Locations'!O9) = TRUE, 0, $C10) -> 0 | P10: =IF(ISNUMBER('III. New Locations'!P9) = TRUE, 0, $C10) -> 0 | Q10: =IF(ISNUMBER('III. New Locations'!Q9) = TRUE, 0, $C10) -> 0 | R10: =IF(ISNUMBER('III. New Locations'!R9) = TRUE, IF('III. New Locations'!R9 >= 0, IF('III. New Locations'!R9 <=1, 0, $C10),$C10),$C10) -> 0 | S10: =IF(ISNUMBER('III. New Locations'!S9) = TRUE, IF('III. New Locations'!S9 >= 0, IF('III. New Locations'!S9 <=1, 0, $C10), $C10), $C10) -> 0 | T10: =IF('III. New Locations'!T9 = "-Unknown-", $C10, 0) -> 0 | U10: =IF(LEN('III. New Locations'!U9)>1, 0, IF(T10 = 0, 0, $C10)) -> 0 | V10: =IF('III. New Locations'!V9 = "Unknown", $C10, 0) -> 0 | W10: =IF(LEN('III. New Locations'!W9)>1, 0, IF(V10 = 0, 0, $C10)) -> 0 | X10: ='III. New Locations'!X9 -> 0 | Y10: =IF(ISNUMBER('III. New Locations'!Y9) = TRUE, IF('III. New Locations'!Y9 >= 1400, IF('III. New Locations'!Y9 <=2100, 0, $C10), $C10), $C10) -> 0 | Z10: =IF(ISNUMBER('III. New Locations'!Z9) = TRUE, IF('III. New Locations'!Z9 >= 1400, IF('III. New Locations'!Z9 <=2100, 0, $C10), $C10), $C10) -> 0 | AA10: =IF(ISNUMBER('III. New Locations'!AA9) = TRUE, IF('III. New Locations'!AA9 >= 1400, IF('III. New Locations'!AA9 <=2100, 0, $C10), $C10), $C10) -> 0 | AC10: =IF(ISNUMBER('III. New Locations'!AC9) = TRUE, IF('III. New Locations'!AC9 >= 0, IF('III. New Locations'!AC9 <=1, 0,$C10),$C10), $C10) -> 0
A11: ='III. New Locations'!A10 -> 8 | C11: =IF(LEN('III. New Locations'!C10) > 2, 1, 0) -> 0 | E11: =IF(LEN('III. New Locations'!E10) = 2, IF('III. New Locations'!E10 = "--", $C11, 0), $C11) -> 0 | F11: =IF(LEN('III. New Locations'!F10) > 4, 0, $C11) -> 0 | G11: =IF(ISNUMBER('III. New Locations'!G10) = TRUE, 0, $C11) -> 0 | H11: =IF(ISNUMBER('III. New Locations'!H10) = TRUE, 0, $C11) -> 0 | I11: =IF(ISNUMBER('III. New Locations'!I10) = TRUE, 0, $C11) -> 0 | J11: =IF(ISNUMBER('III. New Locations'!J10) = TRUE, 0, $C11) -> 0 | K11: =IF(ISNUMBER('III. New Locations'!K10) = TRUE, 0,$C11) -> 0 | M11: =IF(ISNUMBER('III. New Locations'!M10) = TRUE, 0,$C11) -> 0 | O11: =IF(ISNUMBER('III. New Locations'!O10) = TRUE, 0, $C11) -> 0 | P11: =IF(ISNUMBER('III. New Locations'!P10) = TRUE, 0, $C11) -> 0 | Q11: =IF(ISNUMBER('III. New Locations'!Q10) = TRUE, 0, $C11) -> 0 | R11: =IF(ISNUMBER('III. New Locations'!R10) = TRUE, IF('III. New Locations'!R10 >= 0, IF('III. New Locations'!R10 <=1, 0, $C11),$C11),$C11) -> 0 | S11: =IF(ISNUMBER('III. New Locations'!S10) = TRUE, IF('III. New Locations'!S10 >= 0, IF('III. New Locations'!S10 <=1, 0, $C11), $C11), $C11) -> 0 | T11: =IF('III. New Locations'!T10 = "-Unknown-", $C11, 0) -> 0 | U11: =IF(LEN('III. New Locations'!U10)>1, 0, IF(T11 = 0, 0, $C11)) -> 0 | V11: =IF('III. New Locations'!V10 = "Unknown", $C11, 0) -> 0 | W11: =IF(LEN('III. New Locations'!W10)>1, 0, IF(V11 = 0, 0, $C11)) -> 0 | X11: ='III. New Locations'!X10 -> 0 | Y11: =IF(ISNUMBER('III. New Locations'!Y10) = TRUE, IF('III. New Locations'!Y10 >= 1400, IF('III. New Locations'!Y10 <=2100, 0, $C11), $C11), $C11) -> 0 | Z11: =IF(ISNUMBER('III. New Locations'!Z10) = TRUE, IF('III. New Locations'!Z10 >= 1400, IF('III. New Locations'!Z10 <=2100, 0, $C11), $C11), $C11) -> 0 | AA11: =IF(ISNUMBER('III. New Locations'!AA10) = TRUE, IF('III. New Locations'!AA10 >= 1400, IF('III. New Locations'!AA10 <=2100, 0, $C11), $C11), $C11) -> 0 | AC11: =IF(ISNUMBER('III. New Locations'!AC10) = TRUE, IF('III. New Locations'!AC10 >= 0, IF('III. New Locations'!AC10 <=1, 0,$C11),$C11), $C11) -> 0
A12: ='III. New Locations'!A11 -> 9 | C12: =IF(LEN('III. New Locations'!C11) > 2, 1, 0) -> 0 | E12: =IF(LEN('III. New Locations'!E11) = 2, IF('III. New Locations'!E11 = "--", $C12, 0), $C12) -> 0 | F12: =IF(LEN('III. New Locations'!F11) > 4, 0, $C12) -> 0 | G12: =IF(ISNUMBER('III. New Locations'!G11) = TRUE, 0, $C12) -> 0 | H12: =IF(ISNUMBER('III. New Locations'!H11) = TRUE, 0, $C12) -> 0 | I12: =IF(ISNUMBER('III. New Locations'!I11) = TRUE, 0, $C12) -> 0 | J12: =IF(ISNUMBER('III. New Locations'!J11) = TRUE, 0, $C12) -> 0 | K12: =IF(ISNUMBER('III. New Locations'!K11) = TRUE, 0,$C12) -> 0 | M12: =IF(ISNUMBER('III. New Locations'!M11) = TRUE, 0,$C12) -> 0 | O12: =IF(ISNUMBER('III. New Locations'!O11) = TRUE, 0, $C12) -> 0 | P12: =IF(ISNUMBER('III. New Locations'!P11) = TRUE, 0, $C12) -> 0 | Q12: =IF(ISNUMBER('III. New Locations'!Q11) = TRUE, 0, $C12) -> 0 | R12: =IF(ISNUMBER('III. New Locations'!R11) = TRUE, IF('III. New Locations'!R11 >= 0, IF('III. New Locations'!R11 <=1, 0, $C12),$C12),$C12) -> 0 | S12: =IF(ISNUMBER('III. New Locations'!S11) = TRUE, IF('III. New Locations'!S11 >= 0, IF('III. New Locations'!S11 <=1, 0, $C12), $C12), $C12) -> 0 | T12: =IF('III. New Locations'!T11 = "-Unknown-", $C12, 0) -> 0 | U12: =IF(LEN('III. New Locations'!U11)>1, 0, IF(T12 = 0, 0, $C12)) -> 0 | V12: =IF('III. New Locations'!V11 = "Unknown", $C12, 0) -> 0 | W12: =IF(LEN('III. New Locations'!W11)>1, 0, IF(V12 = 0, 0, $C12)) -> 0 | X12: ='III. New Locations'!X11 -> 0 | Y12: =IF(ISNUMBER('III. New Locations'!Y11) = TRUE, IF('III. New Locations'!Y11 >= 1400, IF('III. New Locations'!Y11 <=2100, 0, $C12), $C12), $C12) -> 0 | Z12: =IF(ISNUMBER('III. New Locations'!Z11) = TRUE, IF('III. New Locations'!Z11 >= 1400, IF('III. New Locations'!Z11 <=2100, 0, $C12), $C12), $C12) -> 0 | AA12: =IF(ISNUMBER('III. New Locations'!AA11) = TRUE, IF('III. New Locations'!AA11 >= 1400, IF('III. New Locations'!AA11 <=2100, 0, $C12), $C12), $C12) -> 0 | AC12: =IF(ISNUMBER('III. New Locations'!AC11) = TRUE, IF('III. New Locations'!AC11 >= 0, IF('III. New Locations'!AC11 <=1, 0,$C12),$C12), $C12) -> 0
A13: ='III. New Locations'!A12 -> 10 | C13: =IF(LEN('III. New Locations'!C12) > 2, 1, 0) -> 0 | E13: =IF(LEN('III. New Locations'!E12) = 2, IF('III. New Locations'!E12 = "--", $C13, 0), $C13) -> 0 | F13: =IF(LEN('III. New Locations'!F12) > 4, 0, $C13) -> 0 | G13: =IF(ISNUMBER('III. New Locations'!G12) = TRUE, 0, $C13) -> 0 | H13: =IF(ISNUMBER('III. New Locations'!H12) = TRUE, 0, $C13) -> 0 | I13: =IF(ISNUMBER('III. New Locations'!I12) = TRUE, 0, $C13) -> 0 | J13: =IF(ISNUMBER('III. New Locations'!J12) = TRUE, 0, $C13) -> 0 | K13: =IF(ISNUMBER('III. New Locations'!K12) = TRUE, 0,$C13) -> 0 | M13: =IF(ISNUMBER('III. New Locations'!M12) = TRUE, 0,$C13) -> 0 | O13: =IF(ISNUMBER('III. New Locations'!O12) = TRUE, 0, $C13) -> 0 | P13: =IF(ISNUMBER('III. New Locations'!P12) = TRUE, 0, $C13) -> 0 | Q13: =IF(ISNUMBER('III. New Locations'!Q12) = TRUE, 0, $C13) -> 0 | R13: =IF(ISNUMBER('III. New Locations'!R12) = TRUE, IF('III. New Locations'!R12 >= 0, IF('III. New Locations'!R12 <=1, 0, $C13),$C13),$C13) -> 0 | S13: =IF(ISNUMBER('III. New Locations'!S12) = TRUE, IF('III. New Locations'!S12 >= 0, IF('III. New Locations'!S12 <=1, 0, $C13), $C13), $C13) -> 0 | T13: =IF('III. New Locations'!T12 = "-Unknown-", $C13, 0) -> 0 | U13: =IF(LEN('III. New Locations'!U12)>1, 0, IF(T13 = 0, 0, $C13)) -> 0 | V13: =IF('III. New Locations'!V12 = "Unknown", $C13, 0) -> 0 | W13: =IF(LEN('III. New Locations'!W12)>1, 0, IF(V13 = 0, 0, $C13)) -> 0 | X13: ='III. New Locations'!X12 -> 0 | Y13: =IF(ISNUMBER('III. New Locations'!Y12) = TRUE, IF('III. New Locations'!Y12 >= 1400, IF('III. New Locations'!Y12 <=2100, 0, $C13), $C13), $C13) -> 0 | Z13: =IF(ISNUMBER('III. New Locations'!Z12) = TRUE, IF('III. New Locations'!Z12 >= 1400, IF('III. New Locations'!Z12 <=2100, 0, $C13), $C13), $C13) -> 0 | AA13: =IF(ISNUMBER('III. New Locations'!AA12) = TRUE, IF('III. New Locations'!AA12 >= 1400, IF('III. New Locations'!AA12 <=2100, 0, $C13), $C13), $C13) -> 0 | AC13: =IF(ISNUMBER('III. New Locations'!AC12) = TRUE, IF('III. New Locations'!AC12 >= 0, IF('III. New Locations'!AC12 <=1, 0,$C13),$C13), $C13) -> 0
A14: ='III. New Locations'!A13 -> 11 | C14: =IF(LEN('III. New Locations'!C13) > 2, 1, 0) -> 0 | E14: =IF(LEN('III. New Locations'!E13) = 2, IF('III. New Locations'!E13 = "--", $C14, 0), $C14) -> 0 | F14: =IF(LEN('III. New Locations'!F13) > 4, 0, $C14) -> 0 | G14: =IF(ISNUMBER('III. New Locations'!G13) = TRUE, 0, $C14) -> 0 | H14: =IF(ISNUMBER('III. New Locations'!H13) = TRUE, 0, $C14) -> 0 | I14: =IF(ISNUMBER('III. New Locations'!I13) = TRUE, 0, $C14) -> 0 | J14: =IF(ISNUMBER('III. New Locations'!J13) = TRUE, 0, $C14) -> 0 | K14: =IF(ISNUMBER('III. New Locations'!K13) = TRUE, 0,$C14) -> 0 | M14: =IF(ISNUMBER('III. New Locations'!M13) = TRUE, 0,$C14) -> 0 | O14: =IF(ISNUMBER('III. New Locations'!O13) = TRUE, 0, $C14) -> 0 | P14: =IF(ISNUMBER('III. New Locations'!P13) = TRUE, 0, $C14) -> 0 | Q14: =IF(ISNUMBER('III. New Locations'!Q13) = TRUE, 0, $C14) -> 0 | R14: =IF(ISNUMBER('III. New Locations'!R13) = TRUE, IF('III. New Locations'!R13 >= 0, IF('III. New Locations'!R13 <=1, 0, $C14),$C14),$C14) -> 0 | S14: =IF(ISNUMBER('III. New Locations'!S13) = TRUE, IF('III. New Locations'!S13 >= 0, IF('III. New Locations'!S13 <=1, 0, $C14), $C14), $C14) -> 0 | T14: =IF('III. New Locations'!T13 = "-Unknown-", $C14, 0) -> 0 | U14: =IF(LEN('III. New Locations'!U13)>1, 0, IF(T14 = 0, 0, $C14)) -> 0 | V14: =IF('III. New Locations'!V13 = "Unknown", $C14, 0) -> 0 | W14: =IF(LEN('III. New Locations'!W13)>1, 0, IF(V14 = 0, 0, $C14)) -> 0 | X14: ='III. New Locations'!X13 -> 0 | Y14: =IF(ISNUMBER('III. New Locations'!Y13) = TRUE, IF('III. New Locations'!Y13 >= 1400, IF('III. New Locations'!Y13 <=2100, 0, $C14), $C14), $C14) -> 0 | Z14: =IF(ISNUMBER('III. New Locations'!Z13) = TRUE, IF('III. New Locations'!Z13 >= 1400, IF('III. New Locations'!Z13 <=2100, 0, $C14), $C14), $C14) -> 0 | AA14: =IF(ISNUMBER('III. New Locations'!AA13) = TRUE, IF('III. New Locations'!AA13 >= 1400, IF('III. New Locations'!AA13 <=2100, 0, $C14), $C14), $C14) -> 0 | AC14: =IF(ISNUMBER('III. New Locations'!AC13) = TRUE, IF('III. New Locations'!AC13 >= 0, IF('III. New Locations'!AC13 <=1, 0,$C14),$C14), $C14) -> 0
A15: ='III. New Locations'!A14 -> 12 | C15: =IF(LEN('III. New Locations'!C14) > 2, 1, 0) -> 0 | E15: =IF(LEN('III. New Locations'!E14) = 2, IF('III. New Locations'!E14 = "--", $C15, 0), $C15) -> 0 | F15: =IF(LEN('III. New Locations'!F14) > 4, 0, $C15) -> 0 | G15: =IF(ISNUMBER('III. New Locations'!G14) = TRUE, 0, $C15) -> 0 | H15: =IF(ISNUMBER('III. New Locations'!H14) = TRUE, 0, $C15) -> 0 | I15: =IF(ISNUMBER('III. New Locations'!I14) = TRUE, 0, $C15) -> 0 | J15: =IF(ISNUMBER('III. New Locations'!J14) = TRUE, 0, $C15) -> 0 | K15: =IF(ISNUMBER('III. New Locations'!K14) = TRUE, 0,$C15) -> 0 | M15: =IF(ISNUMBER('III. New Locations'!M14) = TRUE, 0,$C15) -> 0 | O15: =IF(ISNUMBER('III. New Locations'!O14) = TRUE, 0, $C15) -> 0 | P15: =IF(ISNUMBER('III. New Locations'!P14) = TRUE, 0, $C15) -> 0 | Q15: =IF(ISNUMBER('III. New Locations'!Q14) = TRUE, 0, $C15) -> 0 | R15: =IF(ISNUMBER('III. New Locations'!R14) = TRUE, IF('III. New Locations'!R14 >= 0, IF('III. New Locations'!R14 <=1, 0, $C15),$C15),$C15) -> 0 | S15: =IF(ISNUMBER('III. New Locations'!S14) = TRUE, IF('III. New Locations'!S14 >= 0, IF('III. New Locations'!S14 <=1, 0, $C15), $C15), $C15) -> 0 | T15: =IF('III. New Locations'!T14 = "-Unknown-", $C15, 0) -> 0 | U15: =IF(LEN('III. New Locations'!U14)>1, 0, IF(T15 = 0, 0, $C15)) -> 0 | V15: =IF('III. New Locations'!V14 = "Unknown", $C15, 0) -> 0 | W15: =IF(LEN('III. New Locations'!W14)>1, 0, IF(V15 = 0, 0, $C15)) -> 0 | X15: ='III. New Locations'!X14 -> 0 | Y15: =IF(ISNUMBER('III. New Locations'!Y14) = TRUE, IF('III. New Locations'!Y14 >= 1400, IF('III. New Locations'!Y14 <=2100, 0, $C15), $C15), $C15) -> 0 | Z15: =IF(ISNUMBER('III. New Locations'!Z14) = TRUE, IF('III. New Locations'!Z14 >= 1400, IF('III. New Locations'!Z14 <=2100, 0, $C15), $C15), $C15) -> 0 | AA15: =IF(ISNUMBER('III. New Locations'!AA14) = TRUE, IF('III. New Locations'!AA14 >= 1400, IF('III. New Locations'!AA14 <=2100, 0, $C15), $C15), $C15) -> 0 | AC15: =IF(ISNUMBER('III. New Locations'!AC14) = TRUE, IF('III. New Locations'!AC14 >= 0, IF('III. New Locations'!AC14 <=1, 0,$C15),$C15), $C15) -> 0
